{"timestamp":"2025-07-29T13:44:11.870369","level":"info","event":"DAG bundles loaded: dags-folder, example_dags","logger":"airflow.dag_processing.bundles.manager.DagBundlesManager"}
{"timestamp":"2025-07-29T13:44:11.870826","level":"info","event":"Filling up the DagBag from /home/user/airflow/dags/my_first_dag.py","logger":"airflow.models.dagbag.DagBag"}
{"timestamp":"2025-07-29T13:44:12.638791Z","level":"info","event":"Task instance is in running state","chan":"stdout","logger":"task"}
{"timestamp":"2025-07-29T13:44:12.638932Z","level":"info","event":" Previous state of the Task instance: TaskInstanceState.QUEUED","chan":"stdout","logger":"task"}
{"timestamp":"2025-07-29T13:44:12.639057Z","level":"info","event":"Current task name:init_ee","chan":"stdout","logger":"task"}
{"timestamp":"2025-07-29T13:44:12.639122Z","level":"info","event":"Dag name:ndvi_change_detection_pipeline_branching","chan":"stdout","logger":"task"}
{"timestamp":"2025-07-29T13:44:12.640088","level":"error","event":"Task failed with exception","logger":"task","error_detail":[{"exc_type":"FileNotFoundError","exc_value":"[Errno 2] No such file or directory: '/home/user/airflow/service-account.json'","exc_notes":[],"syntax_error":null,"is_cause":false,"frames":[{"filename":"/home/user/airflow_venv_clean/lib/python3.12/site-packages/airflow/sdk/execution_time/task_runner.py","lineno":877,"name":"run"},{"filename":"/home/user/airflow_venv_clean/lib/python3.12/site-packages/airflow/sdk/execution_time/task_runner.py","lineno":1164,"name":"_execute_task"},{"filename":"/home/user/airflow_venv_clean/lib/python3.12/site-packages/airflow/sdk/bases/operator.py","lineno":397,"name":"wrapper"},{"filename":"/home/user/airflow_venv_clean/lib/python3.12/site-packages/airflow/providers/standard/operators/python.py","lineno":217,"name":"execute"},{"filename":"/home/user/airflow_venv_clean/lib/python3.12/site-packages/airflow/providers/standard/operators/python.py","lineno":240,"name":"execute_callable"},{"filename":"/home/user/airflow_venv_clean/lib/python3.12/site-packages/airflow/sdk/execution_time/callback_runner.py","lineno":81,"name":"run"},{"filename":"/home/user/airflow/ndvi_utils.py","lineno":15,"name":"init_ee"},{"filename":"/home/user/airflow_venv_clean/lib/python3.12/site-packages/ee/_helpers.py","lineno":48,"name":"ServiceAccountCredentials"},{"filename":"/home/user/airflow_venv_clean/lib/python3.12/site-packages/google/oauth2/service_account.py","lineno":260,"name":"from_service_account_file"},{"filename":"/home/user/airflow_venv_clean/lib/python3.12/site-packages/google/auth/_service_account_info.py","lineno":78,"name":"from_filename"}],"is_group":false,"exceptions":[]}]}
{"timestamp":"2025-07-29T13:44:12.665878Z","level":"info","event":"Task instance in failure state","chan":"stdout","logger":"task"}
{"timestamp":"2025-07-29T13:44:12.666083Z","level":"info","event":"Task start","chan":"stdout","logger":"task"}
{"timestamp":"2025-07-29T13:44:12.666143Z","level":"info","event":"Task:<Task(PythonOperator): init_ee>","chan":"stdout","logger":"task"}
{"timestamp":"2025-07-29T13:44:12.666180Z","level":"info","event":"Failure caused by [Errno 2] No such file or directory: '/home/user/airflow/service-account.json'","chan":"stdout","logger":"task"}
